Preparing training and test sets...
Creating samples using as look_back = 5
PyDev console: starting.

Python 3.6.3 (v3.6.3:2c5fed86e0, Oct  3 2017, 00:32:08) 
[GCC 4.2.1 (Apple Inc. build 5666) (dot 3)] on darwin
array([[[[0.0199998, 1.       , 1.       , 1.       ]],

        [[0.0199998, 1.       , 1.       , 1.       ]],

        [[0.0059998, 1.       , 1.       , 1.       ]],

        [[0.0070874, 1.       , 1.       , 1.       ]],

        [[0.0099998, 1.       , 1.       , 1.       ]],

        [[0.0157998, 1.       , 1.       , 1.       ]]]])
Traceback (most recent call last):
  File "/Library/Frameworks/Python.framework/Versions/3.6/lib/python3.6/code.py", line 91, in runcode
    exec(code, self.locals)
  File "<input>", line 1, in <module>
TypeError: 'tuple' object is not callable
(1, 6, 1, 4)
array([[[0.0199998, 1.       , 1.       , 1.       ]],

       [[0.0199998, 1.       , 1.       , 1.       ]],

       [[0.0059998, 1.       , 1.       , 1.       ]],

       [[0.0070874, 1.       , 1.       , 1.       ]],

       [[0.0099998, 1.       , 1.       , 1.       ]],

       [[0.0157998, 1.       , 1.       , 1.       ]]])
Traceback (most recent call last):
  File "/Library/Frameworks/Python.framework/Versions/3.6/lib/python3.6/code.py", line 91, in runcode
    exec(code, self.locals)
  File "<input>", line 1, in <module>
IndexError: index 1 is out of bounds for axis 0 with size 1
array([[0.0199998, 1.       , 1.       , 1.       ]])
array([[0.0199998, 1.       , 1.       , 1.       ]])
array([[0.0070874, 1.       , 1.       , 1.       ]])
array([[0.0099998, 1.       , 1.       , 1.       ]])
array([[0.0157998, 1.       , 1.       , 1.       ]])
(1, 6, 1, 4)
array([0])
Traceback (most recent call last):
  File "/Library/Frameworks/Python.framework/Versions/3.6/lib/python3.6/code.py", line 91, in runcode
    exec(code, self.locals)
  File "<input>", line 1, in <module>
NameError: name 'dataset' is not defined
Traceback (most recent call last):
  File "/Library/Frameworks/Python.framework/Versions/3.6/lib/python3.6/code.py", line 91, in runcode
    exec(code, self.locals)
  File "<input>", line 1, in <module>
NameError: name 'dataset' is not defined
