Preparing training and test sets...
Creating samples using as look_back = 400
Traceback (most recent call last):
  File "/Applications/PyCharm.app/Contents/helpers/pydev/pydev_run_in_console.py", line 52, in run_file
    pydev_imports.execfile(file, globals, locals)  # execute the script
  File "/Applications/PyCharm.app/Contents/helpers/pydev/_pydev_imps/_pydev_execfile.py", line 18, in execfile
    exec(compile(contents+"\n", file, 'exec'), glob, loc)
  File "/Users/michele/Fraud_Detection_LSTM_Thesis/LSTM_classifier.py", line 182, in <module>
    x, y = create_dataset(bonifici, 400)
  File "/Users/michele/Fraud_Detection_LSTM_Thesis/LSTM_classifier.py", line 113, in create_dataset
    sequence_x, sequence_y = get_sequences(transactions, look_back)
  File "/Users/michele/Fraud_Detection_LSTM_Thesis/LSTM_classifier.py", line 95, in get_sequences
    i = transactions.index.get_loc(index_last_genuine_transaction)
  File "/Users/michele/PycharmProjects/varie/venv/lib/python3.6/site-packages/pandas/core/indexes/base.py", line 2897, in get_loc
    return self._engine.get_loc(key)
  File "pandas/_libs/index.pyx", line 107, in pandas._libs.index.IndexEngine.get_loc
  File "pandas/_libs/index.pyx", line 109, in pandas._libs.index.IndexEngine.get_loc
TypeError: 'Index(['20141210114729036000984096'], dtype='object', name='indice')' is an invalid key
PyDev console: starting.

Python 3.6.3 (v3.6.3:2c5fed86e0, Oct  3 2017, 00:32:08) 
[GCC 4.2.1 (Apple Inc. build 5666) (dot 3)] on darwin
