Preparing training and test sets
Traceback (most recent call last):
  File "/Applications/PyCharm.app/Contents/helpers/pydev/pydev_run_in_console.py", line 52, in run_file
    pydev_imports.execfile(file, globals, locals)  # execute the script
  File "/Applications/PyCharm.app/Contents/helpers/pydev/_pydev_imps/_pydev_execfile.py", line 18, in execfile
    exec(compile(contents+"\n", file, 'exec'), glob, loc)
  File "/Users/michele/Fraud_Detection_LSTM_Thesis/LSTM_classifier.py", line 91, in <module>
    x_train, y_train = create_dataset(train, look_back=look_back)
  File "/Users/michele/Fraud_Detection_LSTM_Thesis/LSTM_classifier.py", line 57, in create_dataset
    transactions = transactions.drop(["UserID", "Timestamp", "indice"], axis=1)
  File "/Users/michele/PycharmProjects/varie/venv/lib/python3.6/site-packages/pandas/core/frame.py", line 4102, in drop
    errors=errors,
  File "/Users/michele/PycharmProjects/varie/venv/lib/python3.6/site-packages/pandas/core/generic.py", line 3914, in drop
    obj = obj._drop_axis(labels, axis, level=level, errors=errors)
  File "/Users/michele/PycharmProjects/varie/venv/lib/python3.6/site-packages/pandas/core/generic.py", line 3946, in _drop_axis
    new_axis = axis.drop(labels, errors=errors)
  File "/Users/michele/PycharmProjects/varie/venv/lib/python3.6/site-packages/pandas/core/indexes/base.py", line 5340, in drop
    raise KeyError("{} not found in axis".format(labels[mask]))
KeyError: "['indice'] not found in axis"
PyDev console: starting.

Python 3.6.3 (v3.6.3:2c5fed86e0, Oct  3 2017, 00:32:08) 
[GCC 4.2.1 (Apple Inc. build 5666) (dot 3)] on darwin
