Preparing training and test sets
Ci sono 18 serie con 255 utenti.
Ci sono 0 serie con 50 utenti.
Creating the model...
Model: "sequential_1"
_________________________________________________________________
Layer (type)                 Output Shape              Param #   
=================================================================
lstm_1 (LSTM)                (None, 20, 50)            11600     
_________________________________________________________________
lstm_2 (LSTM)                (None, 50)                20200     
_________________________________________________________________
dense_1 (Dense)              (None, 1)                 51        
=================================================================
Total params: 31,851
Trainable params: 31,851
Non-trainable params: 0
_________________________________________________________________
Training model...
Training
Traceback (most recent call last):
  File "/Applications/PyCharm.app/Contents/helpers/pydev/pydev_run_in_console.py", line 52, in run_file
    pydev_imports.execfile(file, globals, locals)  # execute the script
  File "/Applications/PyCharm.app/Contents/helpers/pydev/_pydev_imps/_pydev_execfile.py", line 18, in execfile
    exec(compile(contents+"\n", file, 'exec'), glob, loc)
  File "/Users/michele/Fraud_Detection_LSTM_Thesis/LSTM_classifier.py", line 100, in <module>
    history = LSTM.train_model(model, x_train, y_train, batch_size, epochs, shuffle, validation, ([], []), patience)
  File "/Users/michele/Fraud_Detection_LSTM_Thesis/models/LSTM.py", line 90, in train_model
    history_callback = model.fit(x_train, y_train, epochs=epochs, verbose=2, callbacks=[WandbCallback()])
  File "/Users/michele/PycharmProjects/varie/venv/lib/python3.6/site-packages/keras/engine/training.py", line 1154, in fit
    batch_size=batch_size)
  File "/Users/michele/PycharmProjects/varie/venv/lib/python3.6/site-packages/keras/engine/training.py", line 621, in _standardize_user_data
    exception_prefix='target')
  File "/Users/michele/PycharmProjects/varie/venv/lib/python3.6/site-packages/keras/engine/training_utils.py", line 145, in standardize_input_data
    str(data_shape))
ValueError: Error when checking target: expected dense_1 to have shape (1,) but got array with shape (7,)
PyDev console: starting.

Python 3.6.3 (v3.6.3:2c5fed86e0, Oct  3 2017, 00:32:08) 
[GCC 4.2.1 (Apple Inc. build 5666) (dot 3)] on darwin
