Preparing training and test sets...
Creating samples using as look_back = 5
Traceback (most recent call last):
  File "/Applications/PyCharm.app/Contents/helpers/pydev/pydev_run_in_console.py", line 52, in run_file
    pydev_imports.execfile(file, globals, locals)  # execute the script
  File "/Applications/PyCharm.app/Contents/helpers/pydev/_pydev_imps/_pydev_execfile.py", line 18, in execfile
    exec(compile(contents+"\n", file, 'exec'), glob, loc)
  File "/Users/michele/Fraud_Detection_LSTM_Thesis/LSTM_classifier.py", line 146, in <module>
    create_dataset_for_single_user(bonifici, 5)
  File "/Users/michele/Fraud_Detection_LSTM_Thesis/LSTM_classifier.py", line 94, in create_dataset_for_single_user
    sequence_x, sequence_y = get_sequences(transactions, look_back)
  File "/Users/michele/Fraud_Detection_LSTM_Thesis/LSTM_classifier.py", line 50, in get_sequences
    if transactions[pointer: pointer + 1, "isFraud"] == 0:
  File "/Users/michele/PycharmProjects/varie/venv/lib/python3.6/site-packages/pandas/core/frame.py", line 2980, in __getitem__
    indexer = self.columns.get_loc(key)
  File "/Users/michele/PycharmProjects/varie/venv/lib/python3.6/site-packages/pandas/core/indexes/base.py", line 2897, in get_loc
    return self._engine.get_loc(key)
  File "pandas/_libs/index.pyx", line 107, in pandas._libs.index.IndexEngine.get_loc
  File "pandas/_libs/index.pyx", line 109, in pandas._libs.index.IndexEngine.get_loc
TypeError: '(slice(0, 1, None), 'isFraud')' is an invalid key
PyDev console: starting.

Python 3.6.3 (v3.6.3:2c5fed86e0, Oct  3 2017, 00:32:08) 
[GCC 4.2.1 (Apple Inc. build 5666) (dot 3)] on darwin
