Preparing training and test sets...
Creating samples using as look_back = 5
Traceback (most recent call last):
  File "/Applications/PyCharm.app/Contents/helpers/pydev/pydev_run_in_console.py", line 52, in run_file
    pydev_imports.execfile(file, globals, locals)  # execute the script
  File "/Applications/PyCharm.app/Contents/helpers/pydev/_pydev_imps/_pydev_execfile.py", line 18, in execfile
    exec(compile(contents+"\n", file, 'exec'), glob, loc)
  File "/Users/michele/Fraud_Detection_LSTM_Thesis/LSTM_classifier.py", line 146, in <module>
    create_dataset_for_single_user(bonifici, 5)
  File "/Users/michele/Fraud_Detection_LSTM_Thesis/LSTM_classifier.py", line 94, in create_dataset_for_single_user
    sequence_x, sequence_y = get_sequences(transactions, look_back)
  File "/Users/michele/Fraud_Detection_LSTM_Thesis/LSTM_classifier.py", line 50, in get_sequences
    if transactions.iloc[pointer: pointer + 1, 2] == 0:
  File "/Users/michele/PycharmProjects/varie/venv/lib/python3.6/site-packages/pandas/core/generic.py", line 1555, in __nonzero__
    self.__class__.__name__
ValueError: The truth value of a Series is ambiguous. Use a.empty, a.bool(), a.item(), a.any() or a.all().
PyDev console: starting.

Python 3.6.3 (v3.6.3:2c5fed86e0, Oct  3 2017, 00:32:08) 
[GCC 4.2.1 (Apple Inc. build 5666) (dot 3)] on darwin
indice
20141231154514807000411159    6dcbac66f4a535145a12b922341c06df
20141128154605390000701214    01b79c6f4c9119ef0c95ce13b4367ee0
20141128154605405000605392    01b79c6f4c9119ef0c95ce13b4367ee0
20141128154605499000996878    01b79c6f4c9119ef0c95ce13b4367ee0
20150103214513527000981477    0f623dfc2085ea0eed7b1b42ae54425c
20150204204223494000156898    ce6ad499c96de41ae3228fef5d6352dc
20141212144536756000543697    64ed68e466ba66efabc9de30fd6997b6
20141118074613424000170799    fe30e3bf82366aa6bac955fff72a97a2
20150219102741808000455013    26845cc976879853ecfe4100b2d8d5b6
Name: UserID, dtype: object
indice
20141231154514807000411159    0.093078
20141128154605390000701214    0.012000
20141128154605405000605392    0.015036
20141128154605499000996878    0.025100
20150103214513527000981477    0.020005
20150204204223494000156898    0.002000
20141212144536756000543697    0.000396
20141118074613424000170799    0.011000
20150219102741808000455013    0.003240
Name: Importo, dtype: float64
Traceback (most recent call last):
  File "/Users/michele/PycharmProjects/varie/venv/lib/python3.6/site-packages/pandas/core/indexing.py", line 235, in _has_valid_tuple
    self._validate_key(k, i)
  File "/Users/michele/PycharmProjects/varie/venv/lib/python3.6/site-packages/pandas/core/indexing.py", line 2035, in _validate_key
    "a [{types}]".format(types=self._valid_types)
ValueError: Can only index by location with a [integer, integer slice (START point is INCLUDED, END point is EXCLUDED), listlike of integers, boolean array]

During handling of the above exception, another exception occurred:

Traceback (most recent call last):
  File "/Library/Frameworks/Python.framework/Versions/3.6/lib/python3.6/code.py", line 91, in runcode
    exec(code, self.locals)
  File "<input>", line 1, in <module>
  File "/Users/michele/PycharmProjects/varie/venv/lib/python3.6/site-packages/pandas/core/indexing.py", line 1418, in __getitem__
    return self._getitem_tuple(key)
  File "/Users/michele/PycharmProjects/varie/venv/lib/python3.6/site-packages/pandas/core/indexing.py", line 2092, in _getitem_tuple
    self._has_valid_tuple(tup)
  File "/Users/michele/PycharmProjects/varie/venv/lib/python3.6/site-packages/pandas/core/indexing.py", line 239, in _has_valid_tuple
    "[{types}] types".format(types=self._valid_types)
ValueError: Location based indexing can only have [integer, integer slice (START point is INCLUDED, END point is EXCLUDED), listlike of integers, boolean array] types
