Preparing training and test sets
Traceback (most recent call last):
  File "/Users/michele/PycharmProjects/varie/venv/lib/python3.6/site-packages/pandas/core/indexes/base.py", line 4736, in get_value
    return libindex.get_value_box(s, key)
  File "pandas/_libs/index.pyx", line 51, in pandas._libs.index.get_value_box
  File "pandas/_libs/index.pyx", line 47, in pandas._libs.index.get_value_at
  File "pandas/_libs/util.pxd", line 98, in pandas._libs.util.get_value_at
  File "pandas/_libs/util.pxd", line 83, in pandas._libs.util.validate_indexer
TypeError: 'str' object cannot be interpreted as an integer

During handling of the above exception, another exception occurred:

Traceback (most recent call last):
  File "/Applications/PyCharm.app/Contents/helpers/pydev/pydev_run_in_console.py", line 52, in run_file
    pydev_imports.execfile(file, globals, locals)  # execute the script
  File "/Applications/PyCharm.app/Contents/helpers/pydev/_pydev_imps/_pydev_execfile.py", line 18, in execfile
    exec(compile(contents+"\n", file, 'exec'), glob, loc)
  File "/Users/michele/Fraud_Detection_LSTM_Thesis/LSTM_classifier.py", line 97, in <module>
    x_train, y_train = create_dataset(train, look_back=look_back)
  File "/Users/michele/Fraud_Detection_LSTM_Thesis/LSTM_classifier.py", line 62, in create_dataset
    series_x, series_y = get_series(transactions, labels, look_back)
  File "/Users/michele/Fraud_Detection_LSTM_Thesis/LSTM_classifier.py", line 41, in get_series
    isFraudolent = labels.iloc[0:look_back]["isFraud"].max()
  File "/Users/michele/PycharmProjects/varie/venv/lib/python3.6/site-packages/pandas/core/series.py", line 1068, in __getitem__
    result = self.index.get_value(self, key)
  File "/Users/michele/PycharmProjects/varie/venv/lib/python3.6/site-packages/pandas/core/indexes/base.py", line 4744, in get_value
    raise e1
  File "/Users/michele/PycharmProjects/varie/venv/lib/python3.6/site-packages/pandas/core/indexes/base.py", line 4730, in get_value
    return self._engine.get_value(s, k, tz=getattr(series.dtype, "tz", None))
  File "pandas/_libs/index.pyx", line 80, in pandas._libs.index.IndexEngine.get_value
  File "pandas/_libs/index.pyx", line 88, in pandas._libs.index.IndexEngine.get_value
  File "pandas/_libs/index.pyx", line 131, in pandas._libs.index.IndexEngine.get_loc
  File "pandas/_libs/hashtable_class_helper.pxi", line 1607, in pandas._libs.hashtable.PyObjectHashTable.get_item
  File "pandas/_libs/hashtable_class_helper.pxi", line 1614, in pandas._libs.hashtable.PyObjectHashTable.get_item
KeyError: 'isFraud'
PyDev console: starting.

Python 3.6.3 (v3.6.3:2c5fed86e0, Oct  3 2017, 00:32:08) 
[GCC 4.2.1 (Apple Inc. build 5666) (dot 3)] on darwin
Traceback (most recent call last):
  File "/Library/Frameworks/Python.framework/Versions/3.6/lib/python3.6/code.py", line 91, in runcode
    exec(code, self.locals)
  File "<input>", line 1, in <module>
NameError: name 'x_train' is not defined
